New session
b'============================= test session starts =============================\r\nplatform win32 -- Python 3.6.3, pytest-3.6.2, py-1.5.4, pluggy-0.6.0\r\nrootdir: D:\\WORK\\allure-python\\allure-pytest, inifile:\r\nplugins: allure-pytest-2.4.1\r\ncollected 2 items\r\n\r\ntest\\utf_identifier\\utf_func_name_py3_only_test.py F.                    [100%]\r\n\r\n================================== FAILURES ===================================\r\n____________________________ test_utf_func_d\\xe9j\\xe0_vu ____________________________\r\n\r\n    def test_utf_func_d\\xe9j\\xe0_vu():\r\n        """\r\n        >>> allure_report = getfixture(\'allure_report\')\r\n        >>> assert_that(allure_report,\r\n        ...             has_test_case(\'test_utf_func_d\\xe9j\\xe0_vu\')\r\n        ... )\r\n        """\r\n>       assert False\r\nE       assert False\r\n\r\ntest\\utf_identifier\\utf_func_name_py3_only_test.py:11: AssertionError\r\n===================== 1 failed, 1 passed in 0.05 seconds ======================\r\n'
